Workbook
Name A: #REF!
Name A: #REF!
Name A: #REF!
Name A: #REF!
Name A: #REF!
Name A: #REF!
Name A: #REF!
Name A: #REF!
Name AA: #REF!
Name AA: #REF!
Name AA: #REF!
Name AA: #REF!
Name AA: #REF!
Name AA: #REF!
Name AA: #REF!
Name AA: #REF!
Name AAA: #REF!
Name AAA: #REF!
Name AAA: #REF!
Name AAA: #REF!
Name AAA: #REF!
Name AAA: #REF!
Name AAA: #REF!
Name AAA: #REF!
Name AAAA: #REF!
Name AAAA: #REF!
Name AAAA: #REF!
Name AAAA: #REF!
Name AAAA: #REF!
Name AAAA: #REF!
Name AAAA: #REF!
Name AAAA: #REF!
Name ABC: #REF!
Name ABC: #REF!
Name ABC: #REF!
Name ABC: #REF!
Name ABC: #REF!
Name ABC: #REF!
Name ABC: #REF!
Name ABC: #REF!
Name ad: #REF!
Name ad: #REF!
Name ad: #REF!
Name ad: #REF!
Name ad: #REF!
Name ad: #REF!
Name ad: #REF!
Name ad: #REF!
Name ADDDELETE1: #REF!
Name ADDDELETE1: #REF!
Name ADDDELETE1: #REF!
Name ADDDELETE1: #REF!
Name ADDDELETE1: #REF!
Name ADDDELETE1: #REF!
Name ADDDELETE1: #REF!
Name ADDDELETE1: #REF!
Name ASSUMPTION: #REF!
Name ASSUMPTION: #REF!
Name ASSUMPTION: #REF!
Name ASSUMPTION: #REF!

Sheet BASE
A1: PARTNUMBER | B1: UM | C1: DESCRIÇÃO | D1: DESCRIÇÃO | E1: BOX | F1: ORIGEM | G1: COMMENTS | H1: QTD | I1: Modelo
A2: 1J0121321B | B2: Peça | C2: COVER | D2: TAMPA DO RESERVATORIO DE COMPENSACA | E2: BX3 | F2: Avulsa | H2: 1 | I2: 11180CUM.ModelCode.EE
A3: 22B607359 | B3: Peça | C3: FOUR-WAY VALVE | D3: VALVULA | E3: BX1 | F3: Avulsa | H3: 1 | I3: 11180CUM.ModelCode.EE
A4: 2376119872 | B4: Peça | C4: PIPE CLAMP | D4: BRACADEIRA | E4: SHW | F4: Avulsa | H4: 1 | I4: 11180CUM.ModelCode.EE
A5: 23A131983B | B5: Peça | C5: TUBULACAO | D5: TUBO PLASTICO RESERVATORIO ADBLUE | E5: BX3 | F5: Avulsa | H5: 1 | I5: 11180CUM.ModelCode.EE
A6: 23A131983D | B6: Peça | C6: TUBULACAO | D6: TUBO DE PLASTICO PARA ALIMENTACAO | E6: BX3 | F6: Avulsa | H6: 1 | I6: 11180CUM.ModelCode.EE
A7: 23A131983E | B7: Peça | C7: TUBULACAO | D7: TUBO PLAST RETORNO RESERVATORIO ADBLUE | E7: BX3 | F7: Avulsa | H7: 1 | I7: 11180CUM.ModelCode.EE
A8: 23A201353C | B8: Peça | C8: TUBULACAO COMBUST. | D8: TUBO PLAST P TANQUE PRE FILTRO USO AUTO | E8: BX1 | F8: Avulsa | H8: 1 | I8: 11180CUM.ModelCode.EE
A9: 23A201512 | B9: Peça | C9: FILTROCOMBUSTIVEL | D9: FILTRO DE COMBUSTIVEL P USO AUTOMOTIVO | E9: BX1 | F9: Avulsa | H9: 1 | I9: 11180CUM.ModelCode.EE
A10: 23A253047 | B10: Peça | C10: APOIO | D10: SUPORTE PTUBO GAS DE ESCAPE DE USO AUTO | E10: BX2 | F10: Avulsa | H10: 1 | I10: 11180CUM.ModelCode.EE
A11: 23A253319 | B11: Peça | C11: SUPORTE | D11: SUPORTE DO CATALISADOR TRAS P USO AUTO | E11: BX1 | F11: Avulsa | H11: 1 | I11: 11180CUM.ModelCode.EE
A12: 23A253319A | B12: Peça | C12: SUPORTE | D12: SUPORTE DO CATALISADOR TRAS P USO AUTO | E12: BX1 | F12: Avulsa | H12: 1 | I12: 11180CUM.ModelCode.EE
A13: 23A254253 | B13: Peça | C13: CONVERSORCATALIT. | D13: CONVERSOR CATALITICO PARA USO AUTOMOTIVO | E13: BX3 | F13: Avulsa | H13: 1 | I13: 11180CUM.ModelCode.EE
... A748: TRN607272 | B748: Peça | C748: CONEXÃORT.3/8/X3/8 | D748: CONEX.RT.3/8/X3/8 | E748: SHW | F748: Avulsa | H748: 2 | I748: 17.180. ModelCode.EE

Sheet 2116001_15190OD.2WLJEB.5180_02_
A1: PARTNUMBER | B1: UM | C1: DESCRIÇÃO | D1: BOX | E1: ORIGEM | F1: KNR | G1: CANT. | H1: PUESTO
A2: 377860250 | B2: Peça | C2: WARNING TRIANGLE | D2: BX1 | E2: Avulsa | F2: 2116001 | G2: 1 | H2: 6
A3: 551999616 | B3: Peça | C3: CONNECTING PIECE | D3: SHW | E3: Avulsa | F3: 2116001 | G3: 2 | H3: 5
A4: 22B937548 | B4: Peça | C4: MAIN FUSE BOX | D4: BX3 | E4: Avulsa | F4: 2116001 | G4: 1 | H4: 6
A5: 23B201136B | B5: Peça | C5: BLEEDER VALVE | D5: SHW | E5: Avulsa | F5: 2116001 | G5: 1 | H5: D
A6: 23B607085A | B6: Peça | C6: NIPPLE | D6: SHW | E6: Avulsa | F6: 2116001 | G6: 16 | H6: 4xA + 12xC
A7: 23B607085AE | B7: Peça | C7: NIPPLE | D7: SHW | E7: Avulsa | F7: 2116001 | G7: 1 | H7: C
A8: 23B607085AH | B8: Peça | C8: NIPPLE | D8: SHW | E8: Avulsa | F8: 2116001 | G8: 1 | H8: C
A9: 23B607085B | B9: Peça | C9: NIPPLE | D9: SHW | E9: Avulsa | F9: 2116001 | G9: 3 | H9: 2xA + 1xC
A10: 23B607085E | B10: Peça | C10: NIPPLE | D10: SHW | E10: Avulsa | F10: 2116001 | G10: 3 | H10: C
A11: 23B607085N | B11: Peça | C11: NIPPLE | D11: SHW | E11: Avulsa | F11: 2116001 | G11: 2 | H11: 0
A12: 23B607085Q | B12: Peça | C12: NIPPLE | D12: SHW | E12: Avulsa | F12: 2116001 | G12: 6 | H12: 1x4 + 5xC
A13: 23B607085R | B13: Peça | C13: NIPPLE | D13: SHW | E13: Avulsa | F13: 2116001 | G13: 1 | H13: 5
A14: 23B607085S | B14: Peça | C14: NIPPLE | D14: SHW | E14: Avulsa | F14: 2116001 | G14: 4 | H14: 2xA + 2xC
A15: 23B607415 | B15: Peça | C15: STRAP | D15: SHW | E15: Avulsa | F15: 2116001 | G15: 8 | H15: 4
A16: 23P607085 | B16: Peça | C16: NIPPLE | D16: SHW | E16: Avulsa | F16: 2116001 | G16: 2 | H16: C
A17: 2P0611778 | B17: Peça | C17: CLIP | D17: SHW | E17: Avulsa | F17: 2116001 | G17: 1 | H17: 0
A18: 2P0857567F | B18: Peça | C18: COVER | D18: BX2 | E18: Avulsa | F18: 2116001 | G18: 1 | H18: 6
A19: 2P0857813A1NN | B19: Peça | C19: LAP BELT | D19: BX1 | E19: Avulsa | F19: 2116001 | G19: 1 | H19: 6
A20: 2P0915089E | B20: Peça | C20: BATTERY | D20: BX3 | E20: Avulsa | F20: 2116001 | G20: 2 | H20: 6
A21: 2R0012239B | B21: Peça | C21: LEVER | D21: BX3 | E21: Avulsa | F21: 2116001 | G21: 1 | H21: 6
A22: 2R0419635 | B22: Peça | C22: DETENT PART | D22: SHW | E22: Avulsa | F22: 2116001 | G22: 1 | H22: 6
A23: 2R0422705A | B23: Peça | C23: CLIP | D23: SHW | E23: Avulsa | F23: 2116001 | G23: 1 | H23: 5
A24: 2R0422913 | B24: Peça | C24: PECA DE CONEXAO | D24: SHW | E24: Avulsa | F24: 2116001 | G24: 1 | H24: 1
A25: 2R0607261D | B25: Peça | C25: DRAIN VALVE | D25: SHW | E25: Avulsa | F25: 2116001 | G25: 2 | H25: C
A26: 2R0915509A | B26: Peça | C26: CLIP | D26: SHW | E26: Avulsa | F26: 2116001 | G26: 2 | H26: 6
A27: 2R2803875B | B27: Peça | C27: FASTENER | D27: SHW | E27: Avulsa | F27: 2116001 | G27: 5 | H27: 2x6 + 3xC
A28: 2R2803875C | B28: Peça | C28: FASTENER | D28: SHW | E28: Avulsa | F28: 2116001 | G28: 10 | H28: 0
A29: 2R2803877A | B29: Peça | C29: FASTENER | D29: SHW | E29: Avulsa | F29: 2116001 | G29: 6 | H29: 2x0 + 1x3 + 3x6
A30: 2R2803877AA | B30: Peça | C30: FASTENER | D30: SHW | E30: Avulsa | F30: 2116001 | G30: 8 | H30: 0
A31: 2R2803877AE | B31: Peça | C31: FASTENER | D31: SHW | E31: Avulsa | F31: 2116001 | G31: 1 | H31: 3
A32: 2R2803877AL | B32: Peça | C32: FASTENER | D32: SHW | E32: Avulsa | F32: 2116001 | G32: 2 | H32: 1
A33: 2R2803877CP | B33: Peça | C33: FASTENER | D33: SHW | E33: Avulsa | F33: 2116001 | G33: 2 | H33: 5
A34: 2R2803877F | B34: Peça | C34: PECA DE FIXACAO | D34: SHW | E34: Avulsa | F34: 2116001 | G34: 6 | H34: 0
A35: 2R2803877S | B35: Peça | C35: FASTENER | D35: SHW | E35: Avulsa | F35: 2116001 | G35: 2 | H35: 0
A36: 2R2806223 | B36: Peça | C36: BLIND RIVET | D36: SHW | E36: Avulsa | F36: 2116001 | G36: 2 | H36: 7
A37: 2R2945511 | B37: Peça | C37: SWITCH,BRAKE PEDAL | D37: SHW | E37: Avulsa | F37: 2116001 | G37: 2 | H37: C
A38: 2R2971963 | B38: Peça | C38: PIN HOUSING | D38: SHW | E38: Avulsa | F38: 2116001 | G38: 4 | H38: 4
A39: 2RD201735 | B39: M | C39: HEAT SHRINK TUBING | D39: SHW0 | E39: Avulsa | F39: 2116001 | G39: 9.49 | H39: 4,35x2 +
A40: 2RD507141 | B40: Peça | C40: PLUG | D40: SHW | E40: Avulsa | F40: 2116001 | G40: 1 | H40: A
...

Sheet BOM
B2: xKD BoM 2024 | C2: Fecha de revisión | D2: 45953
B3: VW ARG - Cordoba
A5: 1 | B5: 2 | C5: 3 | D5: 4 | E5: 5 | F5: 6 | G5: 7 | H5: 8 | I5: 9 | J5: 10 | K5: 11 | L5: 12 | M5: 13 | N5: 14 | O5: 15 | P5: 16 | Q5: 17 | R5: 18 | S5: 19 | T5: 20 | U5: 21 | V5: 22 | W5: 23 | X5: 24 | Y5: 25 | Z5: 26 | AA5: 27 | AB5: 28
G6: 9170.TBXSH1.4000 | I6: 11180.TBETV1.4600 | K6: 17.280.24LD5B.4800 | M6: 17280.24JC5B.4340 | O6: 17280.24LC5B.4340 | Q6: 17280.24JD5B.4800 | S6: 17280.27CA5B.3560 | U6: 15190OD.2WLJEB.5180 | Y6: 9.180 TBXSS1 | AA6: 11.180 TBETS1
A7: PARTNUMBER | B7: UM | C7: DESCRIÇÃO INGLÊS | D7: DESCRIÇÃO PORTUGUÊS | E7: BOX | F7: ORIGEM | G7: Cant. | H7: Puesto | I7: Cant.2 | J7: Puesto2 | K7: Cant.3 | L7: Puesto3 | M7: Cant.4 | N7: Puesto4 | O7: Cant.5 | P7: Puesto5 | Q7: Cant.6 | R7: Puesto6 | S7: Cant.7 | T7: Puesto7 | U7: Cant.8 | V7: Puesto8 | W7: Módulo SHW minutería | X7: EMBALAJE | Y7: Cant.9 | Z7: Puesto9 | AA7: Cant.10 | AB7: Puesto10
A8: 357971939 | B8: Peça | C8: KABELKLEMME | D8: KABELKLEMME | E8: SHW | F8: Avulsa | O8: 3 | P8: 6 | W8: 24 | X8: KLT 3214
A9: 377860250 | B9: Peça | C9: WARNING TRIANGLE | D9: TRIANGULO DE SEG | E9: BX1 | F9: Avulsa | H9: =IF(Prueba[[#This Row],[Cant.]]=0,"",IF(OR(Prueba[[#This Row],[Cant.2]]="",Prueba[[#This Row],[Puesto2]]=""),"?",Prueba[[#This Row],[Puesto2]])) | N9: =IF(Prueba[[#This Row],[Cant.4]]=0,"",IF(OR(Prueba[[#This Row],[Cant.6]]="",Prueba[[#This Row],[Puesto6]]=""),"?",Prueba[[#This Row],[Puesto6]])) | P9: =IF(Prueba[[#This Row],[Cant.5]]=0,"",IF(OR(Prueba[[#This Row],[Cant.6]]="",Prueba[[#This Row],[Puesto6]]=""),"?",Prueba[[#This Row],[Puesto6]])) | U9: 1 | V9: 6 | X9: Pieza individual
A10: 2376119871 | B10: Peça | C10: SCHELLE | D10: PRENDEDOR PARA CABO | E10: SHW | F10: Avulsa | H10: =IF(Prueba[[#This Row],[Cant.]]=0,"",IF(OR(Prueba[[#This Row],[Cant.2]]="",Prueba[[#This Row],[Puesto2]]=""),"?",Prueba[[#This Row],[Puesto2]])) | K10: 3 | M10: 4 | N10: =IF(Prueba[[#This Row],[Cant.4]]=0,"",IF(OR(Prueba[[#This Row],[Cant.6]]="",Prueba[[#This Row],[Puesto6]]=""),"?",Prueba[[#This Row],[Puesto6]])) -> 6 | O10: 4 | P10: =IF(Prueba[[#This Row],[Cant.5]]=0,"",IF(OR(Prueba[[#This Row],[Cant.6]]="",Prueba[[#This Row],[Puesto6]]=""),"?",Prueba[[#This Row],[Puesto6]])) -> 6 | Q10: 4 | R10: 6 | S10: 3 | T10: 6 | W10: 32 | X10: KLT 3214
A11: 2376119872 | C11: PIPE CLAMP | D11: PIPE CLAMP | E11: SHW | W11: 16 | X11: KLT 3214 | Y11: 2 | Z11: 5 | AA11: 2 | AB11: 5
A12: 07W145287 | B12: Peça | C12: BUSH | D12: BUCHA USB | E12: SHW | F12: Avulsa | H12: =IF(Prueba[[#This Row],[Cant.]]=0,"",IF(OR(Prueba[[#This Row],[Cant.2]]="",Prueba[[#This Row],[Puesto2]]=""),"?",Prueba[[#This Row],[Puesto2]])) | K12: 1 | M12: 1 | N12: =IF(Prueba[[#This Row],[Cant.4]]=0,"",IF(OR(Prueba[[#This Row],[Cant.6]]="",Prueba[[#This Row],[Puesto6]]=""),"?",Prueba[[#This Row],[Puesto6]])) -> 5 | O12: 1 | P12: =IF(Prueba[[#This Row],[Cant.5]]=0,"",IF(OR(Prueba[[#This Row],[Cant.6]]="",Prueba[[#This Row],[Puesto6]]=""),"?",Prueba[[#This Row],[Puesto6]])) -> 5 | Q12: 1 | R12: 5 | W12: 8 | X12: KLT 3214
A13: 07W145933 | B13: Peça | C13: CORREIA POLY-V | D13: CORREIA POLY | E13: SHW | F13: Avulsa | H13: =IF(Prueba[[#This Row],[Cant.]]=0,"",IF(OR(Prueba[[#This Row],[Cant.2]]="",Prueba[[#This Row],[Puesto2]]=""),"?",Prueba[[#This Row],[Puesto2]])) | N13: =IF(Prueba[[#This Row],[Cant.4]]=0,"",IF(OR(Prueba[[#This Row],[Cant.6]]="",Prueba[[#This Row],[Puesto6]]=""),"?",Prueba[[#This Row],[Puesto6]])) | P13: =IF(Prueba[[#This Row],[Cant.5]]=0,"",IF(OR(Prueba[[#This Row],[Cant.6]]="",Prueba[[#This Row],[Puesto6]]=""),"?",Prueba[[#This Row],[Puesto6]])) | W13: 0 | X13: KLT 3214
A14: 1J0121321B | B14: Peça | C14: COVER | D14: TAMPA DO RESERVATORIO DE COMPENSACA | E14: BX3 | F14: Avulsa | G14: 1 | H14: =IF(Prueba[[#This Row],[Cant.]]=0,"",IF(OR(Prueba[[#This Row],[Cant.2]]="",Prueba[[#This Row],[Puesto2]]=""),"?",Prueba[[#This Row],[Puesto2]])) -> 5 | I14: 1 | J14: 5 | K14: 1 | M14: 1 | N14: =IF(Prueba[[#This Row],[Cant.4]]=0,"",IF(OR(Prueba[[#This Row],[Cant.6]]="",Prueba[[#This Row],[Puesto6]]=""),"?",Prueba[[#This Row],[Puesto6]])) -> 6 | O14: 1 | P14: =IF(Prueba[[#This Row],[Cant.5]]=0,"",IF(OR(Prueba[[#This Row],[Cant.6]]="",Prueba[[#This Row],[Puesto6]]=""),"?",Prueba[[#This Row],[Puesto6]])) -> 6 | Q14: 1 | R14: 6 | S14: 1 | T14: 6 | X14: Pieza individual | Y14: 1 | Z14: 5 | AA14: 1 | AB14: 5
A15: 22B201100 | B15: Peça | C15: NIPPLE | D15: CONECTOR TUBULACAO COMBUSTIVEL USO AUTOM | E15: SHW | F15: Avulsa | H15: =IF(Prueba[[#This Row],[Cant.]]=0,"",IF(OR(Prueba[[#This Row],[Cant.2]]="",Prueba[[#This Row],[Puesto2]]=""),"?",Prueba[[#This Row],[Puesto2]])) | K15: 2 | N15: =IF(Prueba[[#This Row],[Cant.4]]=0,"",IF(OR(Prueba[[#This Row],[Cant.6]]="",Prueba[[#This Row],[Puesto6]]=""),"?",Prueba[[#This Row],[Puesto6]])) | P15: =IF(Prueba[[#This Row],[Cant.5]]=0,"",IF(OR(Prueba[[#This Row],[Cant.6]]="",Prueba[[#This Row],[Puesto6]]=""),"?",Prueba[[#This Row],[Puesto6]])) | W15: 16 | X15: KLT 3214
A16: 22B201512B | B16: Peça | C16: FILTER WITH PRESSU | D16: FILTRO COMBUSTIVEL PARA USO AUTOMOTIVO | E16: BX1 | F16: Avulsa | H16: =IF(Prueba[[#This Row],[Cant.]]=0,"",IF(OR(Prueba[[#This Row],[Cant.2]]="",Prueba[[#This Row],[Puesto2]]=""),"?",Prueba[[#This Row],[Puesto2]])) | K16: 1 | M16: 1 | N16: =IF(Prueba[[#This Row],[Cant.4]]=0,"",IF(OR(Prueba[[#This Row],[Cant.6]]="",Prueba[[#This Row],[Puesto6]]=""),"?",Prueba[[#This Row],[Puesto6]])) -> 1 | O16: 1 | P16: =IF(Prueba[[#This Row],[Cant.5]]=0,"",IF(OR(Prueba[[#This Row],[Cant.6]]="",Prueba[[#This Row],[Puesto6]]=""),"?",Prueba[[#This Row],[Puesto6]])) -> 1 | Q16: 1 | R16: 1 | S16: 1 | T16: 1 | X16: Pieza individual
A17: 22B607359 | B17: Peça | C17: FOUR-WAY VALVE | D17: VALVULA | E17: BX1 | F17: Avulsa | G17: 1 | H17: =IF(Prueba[[#This Row],[Cant.]]=0,"",IF(OR(Prueba[[#This Row],[Cant.2]]="",Prueba[[#This Row],[Puesto2]]=""),"?",Prueba[[#This Row],[Puesto2]])) -> C | I17: 1 | J17: C | N17: =IF(Prueba[[#This Row],[Cant.4]]=0,"",IF(OR(Prueba[[#This Row],[Cant.6]]="",Prueba[[#This Row],[Puesto6]]=""),"?",Prueba[[#This Row],[Puesto6]])) | P17: =IF(Prueba[[#This Row],[Cant.5]]=0,"",IF(OR(Prueba[[#This Row],[Cant.6]]="",Prueba[[#This Row],[Puesto6]]=""),"?",Prueba[[#This Row],[Puesto6]])) | X17: Pieza individual
A18: 22B937548 | B18: Peça | C18: MAIN FUSE BOX | D18: CAIXA FUSIVEL PRINCIPAL | E18: BX3 | F18: Avulsa | H18: =IF(Prueba[[#This Row],[Cant.]]=0,"",IF(OR(Prueba[[#This Row],[Cant.2]]="",Prueba[[#This Row],[Puesto2]]=""),"?",Prueba[[#This Row],[Puesto2]])) | N18: =IF(Prueba[[#This Row],[Cant.4]]=0,"",IF(OR(Prueba[[#This Row],[Cant.6]]="",Prueba[[#This Row],[Puesto6]]=""),"?",Prueba[[#This Row],[Puesto6]])) | P18: =IF(Prueba[[#This Row],[Cant.5]]=0,"",IF(OR(Prueba[[#This Row],[Cant.6]]="",Prueba[[#This Row],[Puesto6]]=""),"?",Prueba[[#This Row],[Puesto6]])) | U18: 1 | V18: 6 | X18: Pieza individual
A19: 2376119872 | B19: Peça | C19: PIPE CLAMP | D19: BRACADEIRA | E19: SHW | F19: Avulsa | G19: 1 | H19: =IF(Prueba[[#This Row],[Cant.]]=0,"",IF(OR(Prueba[[#This Row],[Cant.2]]="",Prueba[[#This Row],[Puesto2]]=""),"?",Prueba[[#This Row],[Puesto2]])) -> 5 | I19: 1 | J19: 5 | N19: =IF(Prueba[[#This Row],[Cant.4]]=0,"",IF(OR(Prueba[[#This Row],[Cant.6]]="",Prueba[[#This Row],[Puesto6]]=""),"?",Prueba[[#This Row],[Puesto6]])) | P19: =IF(Prueba[[#This Row],[Cant.5]]=0,"",IF(OR(Prueba[[#This Row],[Cant.6]]="",Prueba[[#This Row],[Puesto6]]=""),"?",Prueba[[#This Row],[Puesto6]])) | W19: 8 | X19: KLT 3214
A20: 23A131983B | B20: Peça | C20: TUBULACAO | D20: TUBO PLASTICO RESERVATORIO ADBLUE | E20: BX3 | F20: Avulsa | G20: 1 | H20: =IF(Prueba[[#This Row],[Cant.]]=0,"",IF(OR(Prueba[[#This Row],[Cant.2]]="",Prueba[[#This Row],[Puesto2]]=""),"?",Prueba[[#This Row],[Puesto2]])) -> 2 | I20: 1 | J20: 2 | N20: =IF(Prueba[[#This Row],[Cant.4]]=0,"",IF(OR(Prueba[[#This Row],[Cant.6]]="",Prueba[[#This Row],[Puesto6]]=""),"?",Prueba[[#This Row],[Puesto6]])) | P20: =IF(Prueba[[#This Row],[Cant.5]]=0,"",IF(OR(Prueba[[#This Row],[Cant.6]]="",Prueba[[#This Row],[Puesto6]]=""),"?",Prueba[[#This Row],[Puesto6]])) | X20: Pieza individual
A21: 23A131983D | B21: Peça | C21: TUBULACAO | D21: TUBO DE PLASTICO PARA ALIMENTACAO | E21: BX3 | F21: Avulsa | G21: 1 | H21: =IF(Prueba[[#This Row],[Cant.]]=0,"",IF(OR(Prueba[[#This Row],[Cant.2]]="",Prueba[[#This Row],[Puesto2]]=""),"?",Prueba[[#This Row],[Puesto2]])) -> 2 | I21: 1 | J21: 2 | N21: =IF(Prueba[[#This Row],[Cant.4]]=0,"",IF(OR(Prueba[[#This Row],[Cant.6]]="",Prueba[[#This Row],[Puesto6]]=""),"?",Prueba[[#This Row],[Puesto6]])) | P21: =IF(Prueba[[#This Row],[Cant.5]]=0,"",IF(OR(Prueba[[#This Row],[Cant.6]]="",Prueba[[#This Row],[Puesto6]]=""),"?",Prueba[[#This Row],[Puesto6]])) | X21: Pieza individual | Y21: 1 | Z21: 2 | AA21: 1 | AB21: 2
A22: 23A131983E | B22: Peça | C22: TUBULACAO | D22: TUBO PLAST RETORNO RESERVATORIO ADBLUE | E22: BX3 | F22: Avulsa | G22: 1 | H22: =IF(Prueba[[#This Row],[Cant.]]=0,"",IF(OR(Prueba[[#This Row],[Cant.2]]="",Prueba[[#This Row],[Puesto2]]=""),"?",Prueba[[#This Row],[Puesto2]])) -> 2 | I22: 1 | J22: 2 | N22: =IF(Prueba[[#This Row],[Cant.4]]=0,"",IF(OR(Prueba[[#This Row],[Cant.6]]="",Prueba[[#This Row],[Puesto6]]=""),"?",Prueba[[#This Row],[Puesto6]])) | P22: =IF(Prueba[[#This Row],[Cant.5]]=0,"",IF(OR(Prueba[[#This Row],[Cant.6]]="",Prueba[[#This Row],[Puesto6]]=""),"?",Prueba[[#This Row],[Puesto6]])) | X22: Pieza individual | Y22: 1 | Z22: 2 | AA22: 1 | AB22: 2
A23: 23A201353C | B23: Peça | C23: TUBULACAO COMBUST. | D23: TUBO PLAST P TANQUE PRE FILTRO USO AUTO | E23: BX1 | F23: Avulsa | G23: 1 | H23: =IF(Prueba[[#This Row],[Cant.]]=0,"",IF(OR(Prueba[[#This Row],[Cant.2]]="",Prueba[[#This Row],[Puesto2]]=""),"?",Prueba[[#This Row],[Puesto2]])) -> 5 | I23: 1 | J23: 5 | N23: =IF(Prueba[[#This Row],[Cant.4]]=0,"",IF(OR(Prueba[[#This Row],[Cant.6]]="",Prueba[[#This Row],[Puesto6]]=""),"?",Prueba[[#This Row],[Puesto6]])) | P23: =IF(Prueba[[#This Row],[Cant.5]]=0,"",IF(OR(Prueba[[#This Row],[Cant.6]]="",Prueba[[#This Row],[Puesto6]]=""),"?",Prueba[[#This Row],[Puesto6]])) | X23: Pieza individual
A24: 23A201512 | B24: Peça | C24: FILTROCOMBUSTIVEL | D24: FILTRO DE COMBUSTIVEL P USO AUTOMOTIVO | E24: BX1 | F24: Avulsa | G24: 1 | H24: =IF(Prueba[[#This Row],[Cant.]]=0,"",IF(OR(Prueba[[#This Row],[Cant.2]]="",Prueba[[#This Row],[Puesto2]]=""),"?",Prueba[[#This Row],[Puesto2]])) -> 4 | I24: 1 | J24: 4 | N24: =IF(Prueba[[#This Row],[Cant.4]]=0,"",IF(OR(Prueba[[#This Row],[Cant.6]]="",Prueba[[#This Row],[Puesto6]]=""),"?",Prueba[[#This Row],[Puesto6]])) | P24: =IF(Prueba[[#This Row],[Cant.5]]=0,"",IF(OR(Prueba[[#This Row],[Cant.6]]="",Prueba[[#This Row],[Puesto6]]=""),"?",Prueba[[#This Row],[Puesto6]])) | X24: Pieza individual
A25: 23A253319 | B25: Peça | C25: SUPORTE | D25: SUPORTE DO CATALISADOR TRAS P USO AUTO | E25: BX1 | F25: Avulsa | G25: 1 | H25: =IF(Prueba[[#This Row],[Cant.]]=0,"",IF(OR(Prueba[[#This Row],[Cant.2]]="",Prueba[[#This Row],[Puesto2]]=""),"?",Prueba[[#This Row],[Puesto2]])) -> 0 | I25: 1 | J25: 0 | N25: =IF(Prueba[[#This Row],[Cant.4]]=0,"",IF(OR(Prueba[[#This Row],[Cant.6]]="",Prueba[[#This Row],[Puesto6]]=""),"?",Prueba[[#This Row],[Puesto6]])) | P25: =IF(Prueba[[#This Row],[Cant.5]]=0,"",IF(OR(Prueba[[#This Row],[Cant.6]]="",Prueba[[#This Row],[Puesto6]]=""),"?",Prueba[[#This Row],[Puesto6]])) | X25: Pieza individual | Y25: 1 | Z25: 0 | AA25: 1 | AB25: 0
A26: 23A253319A | B26: Peça | C26: SUPORTE | D26: SUPORTE DO CATALISADOR TRAS P USO AUTO | E26: BX1 | F26: Avulsa | G26: 1 | H26: =IF(Prueba[[#This Row],[Cant.]]=0,"",IF(OR(Prueba[[#This Row],[Cant.2]]="",Prueba[[#This Row],[Puesto2]]=""),"?",Prueba[[#This Row],[Puesto2]])) -> 0 | I26: 1 | J26: 0 | N26: =IF(Prueba[[#This Row],[Cant.4]]=0,"",IF(OR(Prueba[[#This Row],[Cant.6]]="",Prueba[[#This Row],[Puesto6]]=""),"?",Prueba[[#This Row],[Puesto6]])) | P26: =IF(Prueba[[#This Row],[Cant.5]]=0,"",IF(OR(Prueba[[#This Row],[Cant.6]]="",Prueba[[#This Row],[Puesto6]]=""),"?",Prueba[[#This Row],[Puesto6]])) | X26: Pieza individual | Y26: 1 | Z26: 0 | AA26: 1 | AB26: 0
A27: 23A254253 | B27: Peça | C27: CONVERSORCATALIT. | D27: CONVERSOR CATALITICO PARA USO AUTOMOTIVO | E27: BX3 | F27: Avulsa | G27: 1 | H27: =IF(Prueba[[#This Row],[Cant.]]=0,"",IF(OR(Prueba[[#This Row],[Cant.2]]="",Prueba[[#This Row],[Puesto2]]=""),"?",Prueba[[#This Row],[Puesto2]])) -> C | I27: 1 | J27: C | N27: =IF(Prueba[[#This Row],[Cant.4]]=0,"",IF(OR(Prueba[[#This Row],[Cant.6]]="",Prueba[[#This Row],[Puesto6]]=""),"?",Prueba[[#This Row],[Puesto6]])) | P27: =IF(Prueba[[#This Row],[Cant.5]]=0,"",IF(OR(Prueba[[#This Row],[Cant.6]]="",Prueba[[#This Row],[Puesto6]]=""),"?",Prueba[[#This Row],[Puesto6]])) | X27: Pieza individual | Y27: 1 | Z27: C | AA27: 1 | AB27: C
A28: 23B000013LI9A | B28: Peça | D28: CABINA | E28: C01 | F28: Avulsa | G28: 1 | H28: 6 | N28: =IF(Prueba[[#This Row],[Cant.4]]=0,"",IF(OR(Prueba[[#This Row],[Cant.6]]="",Prueba[[#This Row],[Puesto6]]=""),"?",Prueba[[#This Row],[Puesto6]])) | P28: =IF(Prueba[[#This Row],[Cant.5]]=0,"",IF(OR(Prueba[[#This Row],[Cant.6]]="",Prueba[[#This Row],[Puesto6]]=""),"?",Prueba[[#This Row],[Puesto6]])) | X28: Pieza individual | Y28: 1 | Z28: 6
A29: 23B000013MI9A | B29: Peça | C29: Cab | D29: KIT CABINE | E29: C01 | F29: Avulsa | H29: =IF(Prueba[[#This Row],[Cant.]]=0,"",IF(OR(Prueba[[#This Row],[Cant.2]]="",Prueba[[#This Row],[Puesto2]]=""),"?",Prueba[[#This Row],[Puesto2]])) | I29: 1 | J29: 6 | N29: =IF(Prueba[[#This Row],[Cant.4]]=0,"",IF(OR(Prueba[[#This Row],[Cant.6]]="",Prueba[[#This Row],[Puesto6]]=""),"?",Prueba[[#This Row],[Puesto6]])) | P29: =IF(Prueba[[#This Row],[Cant.5]]=0,"",IF(OR(Prueba[[#This Row],[Cant.6]]="",Prueba[[#This Row],[Puesto6]]=""),"?",Prueba[[#This Row],[Puesto6]])) | X29: Pieza individual
A30: 23B000013NI9A | C30: Cab | D30: Cab | E30: C01 | H30: =IF(Prueba[[#This Row],[Cant.]]=0,"",IF(OR(Prueba[[#This Row],[Cant.2]]="",Prueba[[#This Row],[Puesto2]]=""),"?",Prueba[[#This Row],[Puesto2]])) | N30: =IF(Prueba[[#This Row],[Cant.4]]=0,"",IF(OR(Prueba[[#This Row],[Cant.6]]="",Prueba[[#This Row],[Puesto6]]=""),"?",Prueba[[#This Row],[Puesto6]])) | P30: =IF(Prueba[[#This Row],[Cant.5]]=0,"",IF(OR(Prueba[[#This Row],[Cant.6]]="",Prueba[[#This Row],[Puesto6]]=""),"?",Prueba[[#This Row],[Puesto6]])) | X30: Pieza individual | AA30: 1 | AB30: 6
A31: 23B000013RI9A | C31: CABIN | D31: CABIN | E31: C01 | H31: =IF(Prueba[[#This Row],[Cant.]]=0,"",IF(OR(Prueba[[#This Row],[Cant.2]]="",Prueba[[#This Row],[Puesto2]]=""),"?",Prueba[[#This Row],[Puesto2]])) | N31: =IF(Prueba[[#This Row],[Cant.4]]=0,"",IF(OR(Prueba[[#This Row],[Cant.6]]="",Prueba[[#This Row],[Puesto6]]=""),"?",Prueba[[#This Row],[Puesto6]])) | P31: =IF(Prueba[[#This Row],[Cant.5]]=0,"",IF(OR(Prueba[[#This Row],[Cant.6]]="",Prueba[[#This Row],[Puesto6]]=""),"?",Prueba[[#This Row],[Puesto6]])) | X31: Pieza individual | AA31: 1 | AB31: 6
A32: 23B000013SI9A | C32: CABIN | D32: CABIN | E32: C01 | H32: =IF(Prueba[[#This Row],[Cant.]]=0,"",IF(OR(Prueba[[#This Row],[Cant.2]]="",Prueba[[#This Row],[Puesto2]]=""),"?",Prueba[[#This Row],[Puesto2]])) | N32: =IF(Prueba[[#This Row],[Cant.4]]=0,"",IF(OR(Prueba[[#This Row],[Cant.6]]="",Prueba[[#This Row],[Puesto6]]=""),"?",Prueba[[#This Row],[Puesto6]])) | P32: =IF(Prueba[[#This Row],[Cant.5]]=0,"",IF(OR(Prueba[[#This Row],[Cant.6]]="",Prueba[[#This Row],[Puesto6]]=""),"?",Prueba[[#This Row],[Puesto6]])) | X32: Pieza individual | Y32: 1 | Z32: 6
A33: 23B000451 | B33: Peça | C33: ETIQUETA ADVERTENENCIA | D33: ETIQUETA ADVERTEN. | E33: SHW | F33: Avulsa | G33: 1 | H33: =IF(Prueba[[#This Row],[Cant.]]=0,"",IF(OR(Prueba[[#This Row],[Cant.2]]="",Prueba[[#This Row],[Puesto2]]=""),"?",Prueba[[#This Row],[Puesto2]])) -> D | I33: 1 | J33: D | K33: 1 | M33: 2 | N33: =IF(Prueba[[#This Row],[Cant.4]]=0,"",IF(OR(Prueba[[#This Row],[Cant.6]]="",Prueba[[#This Row],[Puesto6]]=""),"?",Prueba[[#This Row],[Puesto6]])) -> D | O33: 1 | P33: =IF(Prueba[[#This Row],[Cant.5]]=0,"",IF(OR(Prueba[[#This Row],[Cant.6]]="",Prueba[[#This Row],[Puesto6]]=""),"?",Prueba[[#This Row],[Puesto6]])) -> D | Q33: 2 | R33: D | S33: 1 | T33: D | W33: 16 | X33: KLT 3214 | Y33: 2 | Z33: D | AA33: 2 | AB33: D
A34: 23B000451A | B34: Peça | C34: STICKER | D34: STICKER | E34: SHW | F34: Avulsa | G34: 1 | H34: D | N34: =IF(Prueba[[#This Row],[Cant.4]]=0,"",IF(OR(Prueba[[#This Row],[Cant.6]]="",Prueba[[#This Row],[Puesto6]]=""),"?",Prueba[[#This Row],[Puesto6]])) | P34: =IF(Prueba[[#This Row],[Cant.5]]=0,"",IF(OR(Prueba[[#This Row],[Cant.6]]="",Prueba[[#This Row],[Puesto6]]=""),"?",Prueba[[#This Row],[Puesto6]])) | W34: 8 | X34: KLT 3214
A35: 23B000911A | B35: Peça | C35: ETIQUETA ADESIVA | D35: ETIQUETA ADESIVA | E35: SHW | F35: Avulsa | H35: =IF(Prueba[[#This Row],[Cant.]]=0,"",IF(OR(Prueba[[#This Row],[Cant.2]]="",Prueba[[#This Row],[Puesto2]]=""),"?",Prueba[[#This Row],[Puesto2]])) | K35: 2 | M35: 2 | N35: =IF(Prueba[[#This Row],[Cant.4]]=0,"",IF(OR(Prueba[[#This Row],[Cant.6]]="",Prueba[[#This Row],[Puesto6]]=""),"?",Prueba[[#This Row],[Puesto6]])) -> 4 | O35: 2 | P35: =IF(Prueba[[#This Row],[Cant.5]]=0,"",IF(OR(Prueba[[#This Row],[Cant.6]]="",Prueba[[#This Row],[Puesto6]]=""),"?",Prueba[[#This Row],[Puesto6]])) -> 4 | Q35: 2 | R35: 4 | S35: 1 | T35: 4 | W35: 16 | X35: KLT 3214
A36: 23B100009E | B36: Peça | C36: ENGINE,TRANSMISS | D36: MOTOR/TRANSMISSAO | E36: C04 | F36: Avulsa | H36: =IF(Prueba[[#This Row],[Cant.]]=0,"",IF(OR(Prueba[[#This Row],[Cant.2]]="",Prueba[[#This Row],[Puesto2]]=""),"?",Prueba[[#This Row],[Puesto2]])) | I36: 1 | J36: 5 | N36: =IF(Prueba[[#This Row],[Cant.4]]=0,"",IF(OR(Prueba[[#This Row],[Cant.6]]="",Prueba[[#This Row],[Puesto6]]=""),"?",Prueba[[#This Row],[Puesto6]])) | P36: =IF(Prueba[[#This Row],[Cant.5]]=0,"",IF(OR(Prueba[[#This Row],[Cant.6]]="",Prueba[[#This Row],[Puesto6]]=""),"?",Prueba[[#This Row],[Puesto6]])) | X36: Pieza individual
A37: 23B100009F | B37: Peça | D37: MOTOR/TRANSMISSÃO | E37: C04 | F37: Avulsa | G37: 1 | H37: 5 | N37: =IF(Prueba[[#This Row],[Cant.4]]=0,"",IF(OR(Prueba[[#This Row],[Cant.6]]="",Prueba[[#This Row],[Puesto6]]=""),"?",Prueba[[#This Row],[Puesto6]])) | P37: =IF(Prueba[[#This Row],[Cant.5]]=0,"",IF(OR(Prueba[[#This Row],[Cant.6]]="",Prueba[[#This Row],[Puesto6]]=""),"?",Prueba[[#This Row],[Puesto6]])) | X37: Pieza individual | Y37: 1 | Z37: 5
A38: 23B100009G | C38: ENGINE,TRANSMISS | D38: ENGINE,TRANSMISS | E38: C04 | H38: =IF(Prueba[[#This Row],[Cant.]]=0,"",IF(OR(Prueba[[#This Row],[Cant.2]]="",Prueba[[#This Row],[Puesto2]]=""),"?",Prueba[[#This Row],[Puesto2]])) | N38: =IF(Prueba[[#This Row],[Cant.4]]=0,"",IF(OR(Prueba[[#This Row],[Cant.6]]="",Prueba[[#This Row],[Puesto6]]=""),"?",Prueba[[#This Row],[Puesto6]])) | P38: =IF(Prueba[[#This Row],[Cant.5]]=0,"",IF(OR(Prueba[[#This Row],[Cant.6]]="",Prueba[[#This Row],[Puesto6]]=""),"?",Prueba[[#This Row],[Puesto6]])) | X38: Pieza individual | Y38: 1 | Z38: 5 | AA38: 1 | AB38: 5
A39: 23B100009K | C39: ENGINE,TRANSMISS. | D39: ENGINE,TRANSMISS. | E39: C04 | H39: =IF(Prueba[[#This Row],[Cant.]]=0,"",IF(OR(Prueba[[#This Row],[Cant.2]]="",Prueba[[#This Row],[Puesto2]]=""),"?",Prueba[[#This Row],[Puesto2]])) | N39: =IF(Prueba[[#This Row],[Cant.4]]=0,"",IF(OR(Prueba[[#This Row],[Cant.6]]="",Prueba[[#This Row],[Puesto6]]=""),"?",Prueba[[#This Row],[Puesto6]])) | P39: =IF(Prueba[[#This Row],[Cant.5]]=0,"",IF(OR(Prueba[[#This Row],[Cant.6]]="",Prueba[[#This Row],[Puesto6]]=""),"?",Prueba[[#This Row],[Puesto6]])) | X39: Pieza individual | AA39: 1 | AB39: 5
A40: 23B100009L | C40: ENGINE,TRANSMISS. | D40: ENGINE,TRANSMISS. | E40: C04 | H40: =IF(Prueba[[#This Row],[Cant.]]=0,"",IF(OR(Prueba[[#This Row],[Cant.2]]="",Prueba[[#This Row],[Puesto2]]=""),"?",Prueba[[#This Row],[Puesto2]])) | N40: =IF(Prueba[[#This Row],[Cant.4]]=0,"",IF(OR(Prueba[[#This Row],[Cant.6]]="",Prueba[[#This Row],[Puesto6]]=""),"?",Prueba[[#This Row],[Puesto6]])) | P40: =IF(Prueba[[#This Row],[Cant.5]]=0,"",IF(OR(Prueba[[#This Row],[Cant.6]]="",Prueba[[#This Row],[Puesto6]]=""),"?",Prueba[[#This Row],[Puesto6]])) | X40: Pieza individual | Y40: 1 | Z40: 5
A41: 23B121103 | B41: Peça | C41: MANGUEIRA REFRIG. | D41: MANGUEIRA DE REFRIGERACAO P USO AUTO | E41: BX3 | F41: Avulsa | G41: 1 | H41: =IF(Prueba[[#This Row],[Cant.]]=0,"",IF(OR(Prueba[[#This Row],[Cant.2]]="",Prueba[[#This Row],[Puesto2]]=""),"?",Prueba[[#This Row],[Puesto2]])) -> 5 | I41: 1 | J41: 5 | N41: =IF(Prueba[[#This Row],[Cant.4]]=0,"",IF(OR(Prueba[[#This Row],[Cant.6]]="",Prueba[[#This Row],[Puesto6]]=""),"?",Prueba[[#This Row],[Puesto6]])) | P41: =IF(Prueba[[#This Row],[Cant.5]]=0,"",IF(OR(Prueba[[#This Row],[Cant.6]]="",Prueba[[#This Row],[Puesto6]]=""),"?",Prueba[[#This Row],[Puesto6]])) | X41: Pieza individual | Y41: 1 | Z41: 5 | AA41: 1 | AB41: 5
A42: 23B121103A | B42: Peça | C42: COOLANT HOSE | D42: TUBO DE BORRACHA VULC DE USO AUTOMOTIVO | E42: BX3 | F42: Avulsa | G42: 1 | H42: =IF(Prueba[[#This Row],[Cant.]]=0,"",IF(OR(Prueba[[#This Row],[Cant.2]]="",Prueba[[#This Row],[Puesto2]]=""),"?",Prueba[[#This Row],[Puesto2]])) -> C | I42: 1 | J42: C | N42: =IF(Prueba[[#This Row],[Cant.4]]=0,"",IF(OR(Prueba[[#This Row],[Cant.6]]="",Prueba[[#This Row],[Puesto6]]=""),"?",Prueba[[#This Row],[Puesto6]])) | P42: =IF(Prueba[[#This Row],[Cant.5]]=0,"",IF(OR(Prueba[[#This Row],[Cant.6]]="",Prueba[[#This Row],[Puesto6]]=""),"?",Prueba[[#This Row],[Puesto6]])) | X42: Pieza individual | Y42: 1 | Z42: C | AA42: 1 | AB42: C
...

Sheet 9.180 TBXSS1
A1: Listado maestro de embalajes de componentes Delivery DG 9.180 - TBXSS1 | J1: Rev | K1: =+BOM!D2 -> 45953
A2: item | B2: Materialnumber | C2: Material short text | D2: Uso por _Puesto | E2: _Puesto LF | F2: EMBALAJE Proveedor | G2: Embalaje línea | H2: Módulo de abastecimiento | I2: Medio de Abastecimiento | J2: Nivel | K2: Observaciones | L2: __PowerAppsId__ | M2: revisión
A3: 1 | B3: 23B700025M | C3: CHASSIS | D3: 1 | E3: 0-1 | F3: BCH | G3: Pieza individual | H3: 1 | I3: Carro Bandejas 1 | L3: cf19bd78-a66b-428f-bd0f-fead1c699e11 | M3: 45702 | N3: =+VLOOKUP(B3,BOM!$A$8:$AB$1078,25,0) -> 1 | O3: =+VLOOKUP(B3,BOM!$A$8:$AB$1078,26,0) -> 0 | P3: =+IF(N3=D3,"ok","") -> ok
A4: 2 | B4: 23B500051BS | C4: EIXO TRASEIRO | D4: 1 | E4: A-B | F4: BEX2 | G4: Pieza individual | H4: 1 | I4: Carro E. Trasero | L4: fdb16029-4579-46c8-8c3d-3a5df4a09659 | M4: 45429 | N4: =+VLOOKUP(B4,BOM!$A$8:$AB$1078,25,0) -> 1 | O4: =+VLOOKUP(B4,BOM!$A$8:$AB$1078,26,0) -> A | P4: =+IF(N4=D4,"ok","") -> ok
A5: 3 | B5: 23B121249F | C5: MODULO DE RADIADOR PARA USO AUTOMOTIVO | D5: 1 | E5: C-D | F5: BRA | G5: Pieza individual | H5: 1 | I5: Embalaje original | L5: cfe858d3-a507-4d4d-bbe1-d107b162382c | M5: 45429 | N5: =+VLOOKUP(B5,BOM!$A$8:$AB$1078,25,0) -> 1 | O5: =+VLOOKUP(B5,BOM!$A$8:$AB$1078,26,0) -> C | P5: =+IF(N5=D5,"ok","") -> ok
A6: 4 | B6: 23B601011L | C6: RIMS AND TYRES | D6: 7 | E6: 3 | F6: BRD | G6: Pieza individual | H6: 7 | I6: Rack ruedas | L6: 7c79bea3-f172-497a-a174-3605ca10aebd | M6: 45429 | N6: =+VLOOKUP(B6,BOM!$A$8:$AB$1078,25,0) -> 7 | O6: =+VLOOKUP(B6,BOM!$A$8:$AB$1078,26,0) -> 4 | P6: =+IF(N6=D6,"ok","") -> ok
A7: 5 | B7: 23B422926 | C7: SUPORTE DE TUBO DIRECAO HIDRAULICA | D7: 1 | E7: 0-1 | F7: BX1 | G7: Pieza individual | H7: 1 | I7: Carro Bandejas 1 | J7: Nivel 1 | L7: 79c798d5-f8a1-492a-a2f4-e7282cb288b3 | M7: 45429 | N7: =+VLOOKUP(B7,BOM!$A$8:$AB$1078,25,0) -> 1 | O7: =+VLOOKUP(B7,BOM!$A$8:$AB$1078,26,0) -> 0 | P7: =+IF(N7=D7,"ok","") -> ok
A8: 6 | B8: 23B607110 | C8: SUPORTE DO TUBO DE DESCARGA DO COMPRESSO | D8: 1 | E8: 0-1 | F8: BX1 | G8: Pieza individual | H8: 1 | I8: Carro Bandejas 1 | J8: Nivel 1 | L8: 26ed467d-e10e-43c2-b874-e51b9a8147c7 | M8: 45429 | N8: =+VLOOKUP(B8,BOM!$A$8:$AB$1078,25,0) -> 1 | O8: =+VLOOKUP(B8,BOM!$A$8:$AB$1078,26,0) -> 0 | P8: =+IF(N8=D8,"ok","") -> ok
A9: 7 | B9: 23B611775 | C9: MANGUEIRA DO FREIO ABS MODUL.VALVE | D9: 1 | E9: 0-1 | F9: BX1 | G9: Pieza individual | H9: 1 | I9: Carro Bandejas 1 | J9: Nivel 1 | L9: e7ece783-ecbb-4143-9bfd-252f328d999c | M9: 45429 | N9: =+VLOOKUP(B9,BOM!$A$8:$AB$1078,25,0) -> 1 | O9: =+VLOOKUP(B9,BOM!$A$8:$AB$1078,26,0) -> 0 | P9: =+IF(N9=D9,"ok","") -> ok
A10: 8 | B10: 23B611776 | C10: MANGUEIRA DO FREIO | D10: 1 | E10: 0-1 | F10: BX1 | G10: Pieza individual | H10: 1 | I10: Carro Bandejas 1 | J10: Nivel 1 | L10: 77af007b-a1f0-48af-96bd-b00495de3168 | M10: 45429 | N10: =+VLOOKUP(B10,BOM!$A$8:$AB$1078,25,0) -> 1 | O10: =+VLOOKUP(B10,BOM!$A$8:$AB$1078,26,0) -> 0 | P10: =+IF(N10=D10,"ok","") -> ok
A11: 9 | B11: 23B701693G | C11: REFORCO DA SUSPENSAO PARA USO AUTOMOTIVO | D11: 2 | E11: 0-1 | F11: BX1 | G11: Pieza individual | H11: 2 | I11: Carro Bandejas 1 | J11: Nivel 1 | L11: 87329c53-6709-467a-870c-054740af9623 | M11: 45702 | N11: =+VLOOKUP(B11,BOM!$A$8:$AB$1078,25,0) -> 2 | O11: =+VLOOKUP(B11,BOM!$A$8:$AB$1078,26,0) -> 0 | P11: =+IF(N11=D11,"ok","") -> ok
A12: 10 | B12: 23B807131 | C12: SUPORTE DO PARACHOQUE DE USO AUTOMOTIVO | D12: 2 | E12: 0-1 | F12: BX1 | G12: Pieza individual | H12: 2 | I12: Carro Bandejas 1 | J12: Nivel 1 | L12: e5b19345-6468-4172-96bc-54b134fad50f | M12: 45429 | N12: =+VLOOKUP(B12,BOM!$A$8:$AB$1078,25,0) -> 2 | O12: =+VLOOKUP(B12,BOM!$A$8:$AB$1078,26,0) -> 0 | P12: =+IF(N12=D12,"ok","") -> ok
A13: 11 | B13: 23B819055 | C13: SUPORTE EM ACO PARA TUBO DE USO AUTOMOT | D13: 1 | E13: 0-1 | F13: BX1 | G13: Pieza individual | H13: 1 | I13: Carro Bandejas 1 | J13: Nivel 1 | L13: ee1ed953-0d97-4288-92b5-3a7274cbcf72 | M13: 45429 | N13: =+VLOOKUP(B13,BOM!$A$8:$AB$1078,25,0) -> 1 | O13: =+VLOOKUP(B13,BOM!$A$8:$AB$1078,26,0) -> 0 | P13: =+IF(N13=D13,"ok","") -> ok
A14: 12 | B14: 23B907631G | C14: VALVULA MAGNETICA SOLENOIDE | D14: 1 | E14: 0-1 | F14: BX1 | G14: Pieza individual | H14: 1 | I14: Carro Bandejas 1 | J14: Nivel 1 | L14: d15092c0-3d2a-41c4-b07d-7ae9d52f6c0d | M14: 45429 | N14: =+VLOOKUP(B14,BOM!$A$8:$AB$1078,25,0) -> 1 | O14: =+VLOOKUP(B14,BOM!$A$8:$AB$1078,26,0) -> 0 | P14: =+IF(N14=D14,"ok","") -> ok
A15: 13 | B15: 23B915516 | C15: SUPORTE DE FIXACAO PARA USO AUTOMOTIVO | D15: 1 | E15: 0-1 | F15: BX1 | G15: Pieza individual | H15: 1 | I15: Carro Bandejas 1 | J15: Nivel 1 | L15: 9b1b8d9d-04c7-4fcc-b86e-4deffb900907 | M15: 45429 | N15: =+VLOOKUP(B15,BOM!$A$8:$AB$1078,25,0) -> 1 | O15: =+VLOOKUP(B15,BOM!$A$8:$AB$1078,26,0) -> 0 | P15: =+IF(N15=D15,"ok","") -> ok
A16: 14 | B16: 23B951183 | C16: SUPORTE DA BUZINA DE USO AUTOMOTOR | D16: 1 | E16: 0-1 | F16: BX1 | G16: Pieza individual | H16: 1 | I16: Carro Bandejas 1 | J16: Nivel 1 | L16: a4e8ab3d-0913-42b1-9942-b6ae72e42077 | M16: 45702 | N16: =+VLOOKUP(B16,BOM!$A$8:$AB$1078,25,0) -> 1 | O16: =+VLOOKUP(B16,BOM!$A$8:$AB$1078,26,0) -> 0 | P16: =+IF(N16=D16,"ok","") -> ok
A17: 15 | B17: 23B971003F | C17: SUPORTE DE ACO PARA CABO USO AUTOMOTIVO | D17: 1 | E17: 0-1 | F17: BX1 | G17: Pieza individual | H17: 1 | I17: Carro Bandejas 1 | J17: Nivel 1 | L17: 14ca7773-07d5-455b-b2ca-0afe75ada098 | M17: 45429 | N17: =+VLOOKUP(B17,BOM!$A$8:$AB$1078,25,0) -> 1 | O17: =+VLOOKUP(B17,BOM!$A$8:$AB$1078,26,0) -> 0 | P17: =+IF(N17=D17,"ok","") -> ok
A18: 16 | B18: 23F701693 | C18: STIFFENING | D18: 1 | E18: 0-1 | F18: BX1 | G18: Pieza individual | H18: 1 | I18: Carro Bandejas 1 | J18: Nivel 1 | L18: d8ec0a16-fc21-4399-86cf-c1b0fa93317e | M18: 45429 | N18: =+VLOOKUP(B18,BOM!$A$8:$AB$1078,25,0) -> 1 | O18: =+VLOOKUP(B18,BOM!$A$8:$AB$1078,26,0) -> 0
A19: 17 | B19: 2R0871195 | C19: GALAO | D19: 2 | E19: 0-1 | F19: BX1 | G19: Pieza individual | H19: 2 | I19: Carro Bandejas 1 | J19: Nivel 1 | L19: b1d03c17-21f2-47e7-a097-643baaad9710 | M19: 45429 | N19: =+VLOOKUP(B19,BOM!$A$8:$AB$1078,25,0) -> 2 | O19: =+VLOOKUP(B19,BOM!$A$8:$AB$1078,26,0) -> 0 | P19: =+IF(N19=D19,"ok","") -> ok
A20: 18 | B20: 23B422859 | C20: TUBO | D20: 1 | E20: 0-1 | F20: BX1 | G20: Pieza individual | H20: 1 | I20: Carro Bandejas 1 | J20: Nivel 2 | L20: c0928341-2fd5-49e4-a1f2-c2f928a5f934 | M20: 45429 | N20: =+VLOOKUP(B20,BOM!$A$8:$AB$1078,25,0) -> 1 | O20: =+VLOOKUP(B20,BOM!$A$8:$AB$1078,26,0) -> 1 | P20: =+IF(N20=D20,"ok","") -> ok
A21: 19 | B21: 23B422897 | C21: TUBO DE PRESSAO DIRECAO HIDRAULICA | D21: 1 | E21: 0-1 | F21: BX1 | G21: Pieza individual | H21: 1 | I21: Carro Bandejas 1 | J21: Nivel 2 | L21: 701782d8-1eb6-4014-ac18-e93f4885f3af | M21: 45429 | N21: =+VLOOKUP(B21,BOM!$A$8:$AB$1078,25,0) -> 1 | O21: =+VLOOKUP(B21,BOM!$A$8:$AB$1078,26,0) -> 1 | P21: =+IF(N21=D21,"ok","") -> ok
A22: 20 | B22: 23A253319 | C22: SUPORTE DO CATALISADOR TRAS P USO AUTO | D22: 1 | E22: 0-1 | F22: BX1 | G22: Pieza individual | H22: 1 | I22: Carro Bandejas 1 | J22: Nivel 3 | L22: 3d556680-4f36-48d9-81d5-1c446e893a92 | M22: 45429 | N22: =+VLOOKUP(B22,BOM!$A$8:$AB$1078,25,0) -> 1 | O22: =+VLOOKUP(B22,BOM!$A$8:$AB$1078,26,0) -> 0 | P22: =+IF(N22=D22,"ok","") -> ok
A23: 21 | B23: 23A253319A | C23: SUPORTE DO CATALISADOR TRAS P USO AUTO | D23: 1 | E23: 0-1 | F23: BX1 | G23: Pieza individual | H23: 1 | I23: Carro Bandejas 1 | J23: Nivel 3 | L23: 7258281d-8cd9-477d-836d-3af4f46c91d2 | M23: 45429 | N23: =+VLOOKUP(B23,BOM!$A$8:$AB$1078,25,0) -> 1 | O23: =+VLOOKUP(B23,BOM!$A$8:$AB$1078,26,0) -> 0 | P23: =+IF(N23=D23,"ok","") -> ok
A24: 22 | B24: 23B721482 | C24: TUBO DE PRESSAO DA EMBREAGEM DE USO AUT | D24: 1 | E24: 2 | F24: BX1 | G24: Pieza individual | H24: 1 | I24: Carro Bandejas 2 | J24: Nivel 1 | L24: abbfeee4-0bad-40d8-9d3a-1b0bb837b169 | M24: 45429 | N24: =+VLOOKUP(B24,BOM!$A$8:$AB$1078,25,0) -> 1 | O24: =+VLOOKUP(B24,BOM!$A$8:$AB$1078,26,0) -> 2 | P24: =+IF(N24=D24,"ok","") -> ok
A25: 23 | B25: 23B201173L | C25: RETURN PIPE | D25: 1 | E25: 2 | F25: BX1 | G25: Pieza individual | H25: 1 | I25: Carro Bandejas 2 | J25: Nivel 2 | L25: d0483e7b-ffb8-4b93-a31b-bf6199b43b82 | M25: 45702 | N25: =+VLOOKUP(B25,BOM!$A$8:$AB$1078,25,0) -> 1 | O25: =+VLOOKUP(B25,BOM!$A$8:$AB$1078,26,0) -> 2 | P25: =+IF(N25=D25,"ok","") -> ok
A26: 24 | B26: 23B971011HJ | C26: HARNESS,REAR COMB. LAMP | D26: 1 | E26: 2 | F26: BX1 | G26: Pieza individual | H26: 1 | I26: Carro Bandejas 2 | J26: Nivel 3 | L26: 51b09f03-f970-40a8-8125-105bc52884d3 | M26: 45429 | N26: =+VLOOKUP(B26,BOM!$A$8:$AB$1078,25,0) -> 1 | O26: =+VLOOKUP(B26,BOM!$A$8:$AB$1078,26,0) -> 2 | P26: =+IF(N26=D26,"ok","") -> ok
A27: 25 | B27: 23B131983S | C27: LINE | D27: 1 | E27: 2 | F27: BX1 | G27: Pieza individual | H27: 1 | I27: Carro Bandejas 2 | J27: Nivel 3 | L27: 44b7e6e0-2f7c-4868-b91a-d8c3bf2e4125 | M27: 45429 | N27: =+VLOOKUP(B27,BOM!$A$8:$AB$1078,25,0) -> 1 | O27: =+VLOOKUP(B27,BOM!$A$8:$AB$1078,26,0) -> 2 | P27: =+IF(N27=D27,"ok","") -> ok
A28: 26 | B28: 23B607862H | C28: BRAKE LINE | D28: 2 | E28: 2 | F28: BX1 | G28: Pieza individual | H28: 2 | I28: Carro Bandejas 2 | J28: Nivel 3 | L28: 3d39b6ec-5c00-46f1-b373-82a3387e9e16 | M28: 45702 | N28: =+VLOOKUP(B28,BOM!$A$8:$AB$1078,25,0) -> 2 | O28: =+VLOOKUP(B28,BOM!$A$8:$AB$1078,26,0) -> 2 | P28: =+IF(N28=D28,"ok","") -> ok
A29: 27 | B29: 23B698705P | C29: TUBO DE FREIO | D29: 1 | E29: 2 | F29: BX1 | G29: Pieza individual | H29: 1 | I29: Carro Bandejas 2 | J29: Nivel 3 | L29: 34e8ce9d-e661-40ba-900d-6ee177e1e93b | M29: 45429 | N29: =+VLOOKUP(B29,BOM!$A$8:$AB$1078,25,0) -> 1 | O29: =+VLOOKUP(B29,BOM!$A$8:$AB$1078,26,0) -> 2 | P29: =+IF(N29=D29,"ok","") -> ok
A30: 28 | B30: 2R0253093 | C30: SUPORTE COMPLETO | D30: 2 | E30: 3 | F30: BX1 | G30: Pieza individual | H30: 2 | I30: Carro Bandejas 3 | J30: Nivel 3 | L30: 9828c114-fbbd-4534-a42b-f0308ac18842 | M30: 45702 | N30: =+VLOOKUP(B30,BOM!$A$8:$AB$1078,25,0) -> 2 | O30: =+VLOOKUP(B30,BOM!$A$8:$AB$1078,26,0) -> 3 | P30: =+IF(N30=D30,"ok","") -> ok
... A36: 34 | B36: 23B898171A | C36: CABO DE SEGURANCA P VEICULOS AUTOMOTORES | D36: 1 | E36: 4 | F36: BX1 | G36: Pieza individual | H36: 1 | I36: Carro Bandejas 4 | J36: Nivel 2 | L36: 88fa7866-e4bd-479b-8525-265e43266051 | M36: 45429 | N36: =+VLOOKUP(B36,BOM!$A$8:$AB$1078,25,0) -> 1 | O36: =+VLOOKUP(B36,BOM!$A$8:$AB$1078,26,0) -> 4 | P36: =+IF(N36=D36,"ok","") -> ok
A37: 35 | B37: 23B201353S | C37: FUEL PIPE | D37: 1 | E37: 4 | F37: BX1 | G37: Pieza individual | H37: 1 | I37: Carro Bandejas 4 | J37: Nivel 3 | K37: Cambio de P5 a P4 | L37: 43d9f63a-8a4a-44f3-b966-998273cf0371 | M37: 45429 | N37: =+VLOOKUP(B37,BOM!$A$8:$AB$1078,25,0) -> 1 | O37: =+VLOOKUP(B37,BOM!$A$8:$AB$1078,26,0) -> 2 | P37: =+IF(N37=D37,"ok","") -> ok
A38: 36 | B38: 23B422849A | C38: SUPORTE RESERVATORIO DIRECAO HIDRAULICA | D38: 1 | E38: 5 | F38: BX1 | G38: Pieza individual | H38: 1 | I38: Carro Bandejas 5 | K38: Cambio de medio | L38: dbbf21da-2003-4b03-9aa9-763104ea34f5 | M38: 45429 | N38: =+VLOOKUP(B38,BOM!$A$8:$AB$1078,25,0) -> 1 | O38: =+VLOOKUP(B38,BOM!$A$8:$AB$1078,26,0) -> 5 | P38: =+IF(N38=D38,"ok","") -> ok
A39: 37 | B39: 2TA145171 | C39: RESERVATORIO OLEO | D39: 1 | E39: 5 | F39: BX1 | G39: Pieza individual | H39: 1 | I39: Carro Bandejas 5 | K39: Cambio de medio / puesto | L39: 679f76ba-1d26-42f5-9ea1-36dd37fd7745 | M39: 45429 | N39: =+VLOOKUP(B39,BOM!$A$8:$AB$1078,25,0) -> 1 | O39: =+VLOOKUP(B39,BOM!$A$8:$AB$1078,26,0) -> 5 | P39: =+IF(N39=D39,"ok","") -> ok
A40: 38 | B40: 23B854735C | C40: CANTONEIRA REFORCO DO ESTRIBO DE USO AUT | D40: 2 | E40: 6 | F40: BX1 | G40: Pieza individual | H40: 2 | I40: Carro Bandejas 6 | J40: Nivel 1 | L40: ea9bcf54-808d-49ba-95d8-644368822897 | M40: 45429 | N40: =+VLOOKUP(B40,BOM!$A$8:$AB$1078,25,0) -> 2 | O40: =+VLOOKUP(B40,BOM!$A$8:$AB$1078,26,0) -> 6
A41: 39 | B41: 23B419831D | C41: COIFA DE BORRACHA COLUNA DE DIRECAO | D41: 1 | E41: 6 | F41: BX1 | G41: Pieza individual | H41: 1 | I41: Carro Bandejas 6 | J41: Nivel 2 | L41: be79572a-9632-458c-9c3e-975152b51450 | M41: 45429 | N41: =+VLOOKUP(B41,BOM!$A$8:$AB$1078,25,0) -> 1 | O41: =+VLOOKUP(B41,BOM!$A$8:$AB$1078,26,0) -> 6
A42: 40 | B42: 23F607251A | C42: PRESSURE ACCUMULATOR | D42: 1 | E42: C-D | F42: BX1 | G42: Pieza individual | H42: 1 | I42: Carro premontajes | J42: 1 | L42: 5654bf09-5427-41df-9405-0ef6c3207438 | M42: 45429 | N42: =+VLOOKUP(B42,BOM!$A$8:$AB$1078,25,0) -> 1 | O42: =+VLOOKUP(B42,BOM!$A$8:$AB$1078,26,0) -> C | P42: =+IF(N42=D42,"ok","") -> ok
A43: 41 | B43: 23B607359C | C43: FOUR-WAY VALVE | D43: 1 | E43: C-D | F43: BX1 | G43: Pieza individual | H43: 1 | I43: Carro Bandejas 9 | J43: 1 | K43: CARRO VÁLVULAS | L43: bcf8b25f-e186-4e52-a8c3-afe90f41dfe6 | M43: 45429 | N43: =+VLOOKUP(B43,BOM!$A$8:$AB$1078,25,0) -> 1 | O43: =+VLOOKUP(B43,BOM!$A$8:$AB$1078,26,0) -> C | P43: =+IF(N43=D43,"ok","") -> ok
A44: 42 | B44: 23B607359D | C44: FOUR-WAY VALVE | D44: 1 | E44: C-D | F44: BX1 | G44: Pieza individual | H44: 1 | I44: Carro Bandejas 9 | J44: 1 | K44: CARRO VÁLVULAS | L44: 87631362-9954-407b-9a61-27ac53bf8b07 | M44: 45429 | N44: =+VLOOKUP(B44,BOM!$A$8:$AB$1078,25,0) -> 1 | O44: =+VLOOKUP(B44,BOM!$A$8:$AB$1078,26,0) -> C | P44: =+IF(N44=D44,"ok","") -> ok
A45: 43 | B45: 23P607879B | C45: BRACKET | D45: 1 | E45: C-D | F45: BX1 | G45: Pieza individual | H45: 1 | I45: Carro Bandejas 9 | J45: 2 | K45: CARRO VÁLVULAS | L45: 726d338e-b034-4d6e-a0d3-35d23ea936d8 | M45: 45429 | N45: =+VLOOKUP(B45,BOM!$A$8:$AB$1078,25,0) -> 1 | O45: =+VLOOKUP(B45,BOM!$A$8:$AB$1078,26,0) -> C | P45: =+IF(N45=D45,"ok","") -> ok
...

Sheet 11.180 - TBETS1
A1: Listado maestro de embalajes de componentes Delivery DG 11.180 - TBETS1 | J1: Rev | K1: =+BOM!D2 -> 45953
A2: item | B2: Materialnumber | C2: Material short text | D2: Uso por _Puesto | E2: _Puesto LF | F2: EMBALAJE Proveedor | G2: Embalaje línea | H2: Módulo de abastecimiento | I2: Medio de Abastecimiento | J2: Nivel | K2: Observaciones | L2: __PowerAppsId__ | M2: revisión
A3: 1 | B3: 23B700025L | C3: CHASSIS | D3: 1 | E3: 0-1 | F3: BCH | G3: Pieza individual | H3: 1 | I3: Caballetes | L3: 26891d20-c2c8-4a64-9550-a0ca439348e3 | M3: 45429 | N3: =+VLOOKUP(B3,BOM!$A$8:$AB$1078,27,0) -> 1 | O3: =+VLOOKUP(B3,BOM!$A$8:$AB$1078,28,0) -> 0 | P3: 1
A4: 2 | B4: 23B500048K | C4: REAR AXLE | D4: 1 | E4: A-B | F4: BEX2 | G4: Pieza individual | H4: 1 | I4: Carro E. Trasero | K4: Cambio de referancia | L4: 871d5e40-dbd1-4974-aee4-e4bc89b28792 | M4: 45429 | N4: =+VLOOKUP(B4,BOM!$A$8:$AB$1078,27,0) -> 1 | O4: =+VLOOKUP(B4,BOM!$A$8:$AB$1078,28,0) -> A | P4: =+IF(N4=D4,"ok","") -> ok
A5: 3 | B5: 23H607359E | C5: Silenciador | D5: 1 | E5: C-D | F5: BOX 1 | G5: Pieza individual | H5: 1 | I5: Carro Bandejas 9 | L5: b63fd265-d3a4-4f1e-8480-74f72b537669 | M5: 45429 | N5: =+VLOOKUP(B5,BOM!$A$8:$AB$1078,27,0) -> 1 | O5: =+VLOOKUP(B5,BOM!$A$8:$AB$1078,28,0) -> C | P5: =+IF(N5=D5,"ok","") -> ok
A6: 4 | B6: 23B121249F | C6: MODULO DE RADIADOR PARA USO AUTOMOTIVO | D6: 1 | E6: C-D | F6: BRA | G6: Pieza individual | H6: 1 | I6: Embalaje original | L6: e6818c36-a3e6-4f5a-9e34-429cb1ce9966 | M6: 45429 | N6: =+VLOOKUP(B6,BOM!$A$8:$AB$1078,27,0) -> 1 | O6: =+VLOOKUP(B6,BOM!$A$8:$AB$1078,28,0) -> C | P6: =+IF(N6=D6,"ok","") -> ok
A7: 5 | B7: 23B601011K | C7: DISK WHEEL W.TIRE | D7: 7 | E7: 3 | F7: BRD | G7: Pieza individual | H7: 7 | I7: Rack ruedas | L7: 025b1f38-ab69-40a5-a7f1-e3b13c1ca511 | M7: 45429 | N7: =+VLOOKUP(B7,BOM!$A$8:$AB$1078,27,0) -> 7 | O7: =+VLOOKUP(B7,BOM!$A$8:$AB$1078,28,0) -> 4 | P7: =+IF(N7=D7,"ok","") -> ok
A8: 6 | B8: 23B422926 | C8: SUPORTE DE TUBO DIRECAO HIDRAULICA | D8: 1 | E8: 0-1 | F8: BX1 | G8: Pieza individual | H8: 1 | I8: Carro Bandejas 1 | J8: Nivel 1 | L8: 9abcc3a1-2a6e-4b9a-a76c-a9cb682da192 | M8: 45429 | N8: =+VLOOKUP(B8,BOM!$A$8:$AB$1078,27,0) -> 1 | O8: =+VLOOKUP(B8,BOM!$A$8:$AB$1078,28,0) -> 0 | P8: =+IF(N8=D8,"ok","") -> ok
A9: 7 | B9: 23B607110 | C9: SUPORTE DO TUBO DE DESCARGA DO COMPRESSO | D9: 1 | E9: 0-1 | F9: BX1 | G9: Pieza individual | H9: 1 | I9: Carro Bandejas 1 | J9: Nivel 1 | L9: 83eb70dc-5596-40cf-aabf-e5bd07c93365 | M9: 45429 | N9: =+VLOOKUP(B9,BOM!$A$8:$AB$1078,27,0) -> 1 | O9: =+VLOOKUP(B9,BOM!$A$8:$AB$1078,28,0) -> 0 | P9: =+IF(N9=D9,"ok","") -> ok
A10: 8 | B10: 23B611775 | C10: MANGUEIRA DO FREIO ABS MODUL.VALVE | D10: 1 | E10: 0-1 | F10: BX1 | G10: Pieza individual | H10: 1 | I10: Carro Bandejas 1 | J10: Nivel 1 | L10: 1540cd48-5f30-4202-a4ee-0a0e870ff1de | M10: 45429 | N10: =+VLOOKUP(B10,BOM!$A$8:$AB$1078,27,0) -> 1 | O10: =+VLOOKUP(B10,BOM!$A$8:$AB$1078,28,0) -> 0 | P10: =+IF(N10=D10,"ok","") -> ok
A11: 9 | B11: 23B611776 | C11: MANGUEIRA DO FREIO | D11: 1 | E11: 0-1 | F11: BX1 | G11: Pieza individual | H11: 1 | I11: Carro Bandejas 1 | J11: Nivel 1 | L11: 43657a1a-db79-4f66-9e57-99184638ddbd | M11: 45429 | N11: =+VLOOKUP(B11,BOM!$A$8:$AB$1078,27,0) -> 1 | O11: =+VLOOKUP(B11,BOM!$A$8:$AB$1078,28,0) -> 0 | P11: =+IF(N11=D11,"ok","") -> ok
A12: 10 | B12: 23B701693G | C12: REFORCO DA SUSPENSAO PARA USO AUTOMOTIVO | D12: 2 | E12: 0-1 | F12: BX1 | G12: Pieza individual | H12: 2 | I12: Carro Bandejas 1 | J12: Nivel 1 | L12: 676748de-ba9b-495f-8512-7683667e1132 | M12: 45429 | N12: =+VLOOKUP(B12,BOM!$A$8:$AB$1078,27,0) -> 2 | O12: =+VLOOKUP(B12,BOM!$A$8:$AB$1078,28,0) -> 0 | P12: =+IF(N12=D12,"ok","") -> ok
A13: 11 | B13: 23B807131 | C13: SUPORTE DO PARACHOQUE DE USO AUTOMOTIVO | D13: 2 | E13: 0-1 | F13: BX1 | G13: Pieza individual | H13: 2 | I13: Carro Bandejas 1 | J13: Nivel 1 | L13: d77926ab-e96d-40d2-b6f6-ce05541bcc30 | M13: 45429 | N13: =+VLOOKUP(B13,BOM!$A$8:$AB$1078,27,0) -> 2 | O13: =+VLOOKUP(B13,BOM!$A$8:$AB$1078,28,0) -> 0 | P13: =+IF(N13=D13,"ok","") -> ok
A14: 12 | B14: 23B819055 | C14: SUPORTE EM ACO PARA TUBO DE USO AUTOMOT | D14: 1 | E14: 0-1 | F14: BX1 | G14: Pieza individual | H14: 1 | I14: Carro Bandejas 1 | J14: Nivel 1 | L14: bd486d1c-b1e4-4e57-9bff-9180a7be1691 | M14: 45429 | N14: =+VLOOKUP(B14,BOM!$A$8:$AB$1078,27,0) -> 1 | O14: =+VLOOKUP(B14,BOM!$A$8:$AB$1078,28,0) -> 0 | P14: =+IF(N14=D14,"ok","") -> ok
A15: 13 | B15: 23B907631B | C15: SOLENOID VALVE | D15: 1 | E15: 0-1 | F15: BX1 | G15: Pieza individual | H15: 1 | I15: Carro Bandejas 1 | J15: Nivel 1 | K15: 06-06-25 Opcional de 23B907631G | L15: aba9fd5e-0029-4005-b7a8-0057356c27cb | M15: 45429 | N15: =+VLOOKUP(B15,BOM!$A$8:$AB$1078,27,0) -> 1 | O15: =+VLOOKUP(B15,BOM!$A$8:$AB$1078,28,0) -> 0 | P15: =+IF(N15=D15,"ok","") -> ok
A16: 14 | B16: 23B907631G | C16: VALVULA MAGNETICA SOLENOIDE | D16: 1 | E16: 0-1 | F16: BX1 | G16: Pieza individual | H16: 1 | I16: Carro Bandejas 1 | J16: Nivel 1 | L16: 6791d62d-8a44-4ddd-a703-8a82cce0b78c | M16: 45429 | N16: =+VLOOKUP(B16,BOM!$A$8:$AB$1078,27,0) -> 1 | O16: =+VLOOKUP(B16,BOM!$A$8:$AB$1078,28,0) -> 0 | P16: =+IF(N16=D16,"ok","") -> ok
A17: 15 | B17: 23B915516 | C17: SUPORTE DE FIXACAO PARA USO AUTOMOTIVO | D17: 1 | E17: 0-1 | F17: BX1 | G17: Pieza individual | H17: 1 | I17: Carro Bandejas 1 | J17: Nivel 1 | L17: 9e03d204-b266-4160-8332-df895b5a4799 | M17: 45702 | N17: =+VLOOKUP(B17,BOM!$A$8:$AB$1078,27,0) -> 1 | O17: =+VLOOKUP(B17,BOM!$A$8:$AB$1078,28,0) -> 0 | P17: =+IF(N17=D17,"ok","") -> ok
A18: 16 | B18: 23B951183 | C18: SUPORTE DA BUZINA DE USO AUTOMOTOR | D18: 1 | E18: 0-1 | F18: BX1 | G18: Pieza individual | H18: 1 | I18: Carro Bandejas 1 | J18: Nivel 1 | L18: 6851eaeb-da67-4a82-ba33-edb48e7bb47d | M18: 45429 | N18: =+VLOOKUP(B18,BOM!$A$8:$AB$1078,27,0) -> 1 | O18: =+VLOOKUP(B18,BOM!$A$8:$AB$1078,28,0) -> 0 | P18: =+IF(N18=D18,"ok","") -> ok
A19: 17 | B19: 23B971003F | C19: SUPORTE DE ACO PARA CABO USO AUTOMOTIVO | D19: 1 | E19: 0-1 | F19: BX1 | G19: Pieza individual | H19: 1 | I19: Carro Bandejas 1 | J19: Nivel 1 | L19: 6973671c-7aee-4b75-84d7-b39a28288fed | M19: 45429 | N19: =+VLOOKUP(B19,BOM!$A$8:$AB$1078,27,0) -> 1 | O19: =+VLOOKUP(B19,BOM!$A$8:$AB$1078,28,0) -> 0 | P19: =+IF(N19=D19,"ok","") -> ok
A20: 18 | B20: 23F701693 | C20: STIFFENING | D20: 1 | E20: 0-1 | F20: BX1 | G20: Pieza individual | H20: 1 | I20: Carro Bandejas 1 | J20: Nivel 1 | L20: e1cb16a5-211c-4d87-9331-1e56884c172a | M20: 45702 | N20: =+VLOOKUP(B20,BOM!$A$8:$AB$1078,27,0) -> 1 | O20: =+VLOOKUP(B20,BOM!$A$8:$AB$1078,28,0) -> 0 | P20: =+IF(N20=D20,"ok","") -> ok
A21: 19 | B21: 2R0871195 | C21: GALAO | D21: 2 | E21: 0-1 | F21: BX1 | G21: Pieza individual | H21: 2 | I21: Carro Bandejas 1 | J21: Nivel 1 | L21: cf19f0c0-1291-4906-a797-f913c3a2f399 | M21: 45429 | N21: =+VLOOKUP(B21,BOM!$A$8:$AB$1078,27,0) -> 2 | O21: =+VLOOKUP(B21,BOM!$A$8:$AB$1078,28,0) -> 0 | P21: =+IF(N21=D21,"ok","") -> ok
A22: 20 | B22: 23B422859 | C22: TUBO | D22: 1 | E22: 0-1 | F22: BX1 | G22: Pieza individual | H22: 1 | I22: Carro Bandejas 1 | J22: Nivel 2 | L22: 5321e68e-3a37-45eb-8462-a249e91400fe | M22: 45429 | N22: =+VLOOKUP(B22,BOM!$A$8:$AB$1078,27,0) -> 1 | O22: =+VLOOKUP(B22,BOM!$A$8:$AB$1078,28,0) -> 1 | P22: =+IF(N22=D22,"ok","") -> ok
A23: 21 | B23: 23B422897 | C23: TUBO DE PRESSAO DIRECAO HIDRAULICA | D23: 1 | E23: 0-1 | F23: BX1 | G23: Pieza individual | H23: 1 | I23: Carro Bandejas 1 | J23: Nivel 2 | L23: a5e60cd0-5082-4f1a-8f15-3b995938b109 | M23: 45429 | N23: =+VLOOKUP(B23,BOM!$A$8:$AB$1078,27,0) -> 1 | O23: =+VLOOKUP(B23,BOM!$A$8:$AB$1078,28,0) -> 1 | P23: =+IF(N23=D23,"ok","") -> ok
A24: 22 | B24: 23A253319 | C24: SUPORTE DO CATALISADOR TRAS P USO AUTO | D24: 1 | E24: 0-1 | F24: BX1 | G24: Pieza individual | H24: 1 | I24: Carro Bandejas 1 | J24: Nivel 3 | L24: decce896-95a0-4362-8c55-48f947411edd | M24: 45429 | N24: =+VLOOKUP(B24,BOM!$A$8:$AB$1078,27,0) -> 1 | O24: =+VLOOKUP(B24,BOM!$A$8:$AB$1078,28,0) -> 0 | P24: =+IF(N24=D24,"ok","") -> ok
A25: 23 | B25: 23A253319A | C25: SUPORTE DO CATALISADOR TRAS P USO AUTO | D25: 1 | E25: 0-1 | F25: BX1 | G25: Pieza individual | H25: 1 | I25: Carro Bandejas 1 | J25: Nivel 3 | L25: c35c1214-f3a9-4ab1-9867-c98e2f5ccf7f | M25: 45702 | N25: =+VLOOKUP(B25,BOM!$A$8:$AB$1078,27,0) -> 1 | O25: =+VLOOKUP(B25,BOM!$A$8:$AB$1078,28,0) -> 0 | P25: =+IF(N25=D25,"ok","") -> ok
A26: 24 | B26: 23B721482 | C26: TUBO DE PRESSAO DA EMBREAGEM DE USO AUT | D26: 1 | E26: 2 | F26: BX1 | G26: Pieza individual | H26: 1 | I26: Carro Bandejas 2 | J26: Nivel 1 | L26: 4dad8800-cbc7-43bb-8930-f3c41f094011 | M26: 45429 | N26: =+VLOOKUP(B26,BOM!$A$8:$AB$1078,27,0) -> 1 | O26: =+VLOOKUP(B26,BOM!$A$8:$AB$1078,28,0) -> 2 | P26: =+IF(N26=D26,"ok","") -> ok
A27: 25 | B27: 23B201173L | C27: RETURN PIPE | D27: 1 | E27: 2 | F27: BX1 | G27: Pieza individual | H27: 1 | I27: Carro Bandejas 2 | J27: Nivel 2 | L27: 0d608ca2-2b32-4c0d-a8fe-9de771c56da2 | M27: 45702 | N27: =+VLOOKUP(B27,BOM!$A$8:$AB$1078,27,0) -> 1 | O27: =+VLOOKUP(B27,BOM!$A$8:$AB$1078,28,0) -> 2 | P27: =+IF(N27=D27,"ok","") -> ok
... A29: 27 | B29: 23B607862H | C29: BRAKE LINE | D29: 2 | E29: 2 | F29: BX1 | G29: Pieza individual | H29: 2 | I29: Carro Bandejas 2 | J29: Nivel 3 | L29: 989d6938-d5f4-4125-8a90-753d5175960f | M29: 45702 | N29: =+VLOOKUP(B29,BOM!$A$8:$AB$1078,27,0) -> 2 | O29: =+VLOOKUP(B29,BOM!$A$8:$AB$1078,28,0) -> 2 | P29: =+IF(N29=D29,"ok","") -> ok
A30: 28 | B30: 23B698705G | C30: TUBO DE FREIO DE USO AUTOMOTIVO | D30: 1 | E30: 2 | F30: BX1 | G30: Pieza individual | I30: Carro Bandejas 2 | J30: Nivel 3 | L30: 6c37d69d-c5e8-459e-bc6a-e7b7066f241e | M30: 45702 | N30: =+VLOOKUP(B30,BOM!$A$8:$AB$1078,27,0) | O30: =+VLOOKUP(B30,BOM!$A$8:$AB$1078,28,0) | P30: =+IF(N30=D30,"ok","")
A31: 29 | B31: 23B971011HK | C31: HARNESS,REAR COMB. LAMP | D31: 1 | E31: 2 | F31: BX1 | G31: Pieza individual | H31: 1 | I31: Carro Bandejas 2 | J31: Nivel 3 | L31: 196a794c-0846-42f5-881e-1f5801e272aa | M31: 45702 | N31: =+VLOOKUP(B31,BOM!$A$8:$AB$1078,27,0) -> 1 | O31: =+VLOOKUP(B31,BOM!$A$8:$AB$1078,28,0) -> 2 | P31: =+IF(N31=D31,"ok","") -> ok
A32: 30 | B32: 2R0253093 | C32: SUPORTE COMPLETO | D32: 2 | E32: 3 | F32: BX1 | G32: Pieza individual | H32: 2 | I32: Carro Bandejas 3 | J32: Nivel 3 | L32: a6343ba9-ea21-45b4-97bf-db18240ad415 | M32: 45429 | N32: =+VLOOKUP(B32,BOM!$A$8:$AB$1078,27,0) -> 2 | O32: =+VLOOKUP(B32,BOM!$A$8:$AB$1078,28,0) -> 3 | P32: =+IF(N32=D32,"ok","") -> ok
A33: 31 | B33: 23B201512D | C33: FILTER W/ PRESSURE REGULATOR | D33: 1 | E33: 4 | F33: BX1 | G33: Pieza individual | H33: 1 | I33: Carro Bandejas 4 | J33: Nivel 1 | L33: 042786b5-85d1-473a-bafb-6c79295f0406 | M33: 45429 | N33: =+VLOOKUP(B33,BOM!$A$8:$AB$1078,27,0) -> 1 | O33: =+VLOOKUP(B33,BOM!$A$8:$AB$1078,28,0) -> 4 | P33: =+IF(N33=D33,"ok","") -> ok
A34: 32 | B34: 23B899330 | C34: ABRACADEIRA BARRA DE TORCAO | D34: 2 | E34: 4 | F34: BX1 | G34: Pieza individual | H34: 2 | I34: Carro Bandejas 4 | J34: Nivel 1 | L34: d0fce3b5-99e7-497a-b9ca-2dc9350d3432 | M34: 45429 | N34: =+VLOOKUP(B34,BOM!$A$8:$AB$1078,27,0) -> 2 | O34: =+VLOOKUP(B34,BOM!$A$8:$AB$1078,28,0) -> 4 | P34: =+IF(N34=D34,"ok","") -> ok
A35: 33 | B35: T15507139 | C35: SUPORTE | D35: 1 | E35: 4 | F35: BX1 | G35: Pieza individual | H35: 1 | I35: Carro Bandejas 4 | J35: Nivel 1 | L35: fcd8fdd4-8e66-48bf-868c-b431afb4c71b | M35: 45429 | N35: =+VLOOKUP(B35,BOM!$A$8:$AB$1078,27,0) -> 1 | O35: =+VLOOKUP(B35,BOM!$A$8:$AB$1078,28,0) -> 4 | P35: =+IF(N35=D35,"ok","") -> ok
A36: 34 | B36: 23B607462B | C36: TUBO DESCARGA COMPRESSOR P USO AUTOMO | D36: 1 | E36: 4 | F36: BX1 | G36: Pieza individual | H36: 1 | I36: Carro Bandejas 4 | J36: Nivel 2 | L36: 24fea796-1a1f-4554-91eb-67b4b897f515 | M36: 45429 | N36: =+VLOOKUP(B36,BOM!$A$8:$AB$1078,27,0) -> 1 | O36: =+VLOOKUP(B36,BOM!$A$8:$AB$1078,28,0) -> 4 | P36: =+IF(N36=D36,"ok","") -> ok
A37: 35 | B37: 23B898171 | C37: CABO DE RETENCAO PARA USO AUTOMOTIVO | D37: 1 | E37: 4 | F37: BX1 | G37: Pieza individual | H37: 1 | I37: Carro Bandejas 4 | J37: Nivel 2 | L37: e2e38f64-4809-4dee-8f60-31e3ed154234 | M37: 45429 | N37: =+VLOOKUP(B37,BOM!$A$8:$AB$1078,27,0) -> 1 | O37: =+VLOOKUP(B37,BOM!$A$8:$AB$1078,28,0) -> 4 | P37: =+IF(N37=D37,"ok","") -> ok
A38: 36 | B38: 23B898171A | C38: CABO DE SEGURANCA P VEICULOS AUTOMOTORES | D38: 1 | E38: 4 | F38: BX1 | G38: Pieza individual | H38: 1 | I38: Carro Bandejas 4 | J38: Nivel 2 | L38: 2cabbf77-707b-406e-aaa4-fc6b57daa5e8 | M38: 45429 | N38: =+VLOOKUP(B38,BOM!$A$8:$AB$1078,27,0) -> 1 | O38: =+VLOOKUP(B38,BOM!$A$8:$AB$1078,28,0) -> 4 | P38: =+IF(N38=D38,"ok","") -> ok
A39: 37 | B39: 23B201353S | C39: FUEL PIPE | D39: 1 | E39: 4 | F39: BX1 | G39: Pieza individual | H39: 1 | I39: Carro Bandejas 4 | J39: Nivel 3 | K39: cambio de P5 a P4 | L39: 19895265-1c4d-4a6f-9bb9-2fbfc57c1051 | M39: 45429 | N39: =+VLOOKUP(B39,BOM!$A$8:$AB$1078,27,0) -> 1 | O39: =+VLOOKUP(B39,BOM!$A$8:$AB$1078,28,0) -> 2 | P39: =+IF(N39=D39,"ok","") -> ok
A40: 38 | B40: 23B422849A | C40: SUPORTE RESERVATORIO DIRECAO HIDRAULICA | D40: 1 | E40: 5 | F40: BX1 | G40: Pieza individual | H40: 1 | I40: Carro Bandejas 5 | K40: Cambio de medio | L40: dd40c031-08a6-4f78-94a3-9ec84444449a | M40: 45429 | N40: =+VLOOKUP(B40,BOM!$A$8:$AB$1078,27,0) -> 1 | O40: =+VLOOKUP(B40,BOM!$A$8:$AB$1078,28,0) -> 5 | P40: =+IF(N40=D40,"ok","") -> ok
A41: 39 | B41: 2TA145171 | C41: RESERVATORIO OLEO | D41: 1 | E41: 5 | F41: BX1 | G41: Pieza individual | H41: 1 | I41: Carro Bandejas 5 | K41: Cambio de medio / puesto | L41: fa827191-2285-4b7f-aac4-5296f960118e | M41: 45429 | N41: =+VLOOKUP(B41,BOM!$A$8:$AB$1078,27,0) -> 1 | O41: =+VLOOKUP(B41,BOM!$A$8:$AB$1078,28,0) -> 5 | P41: =+IF(N41=D41,"ok","") -> ok
...

Sheet 17280.24JC5B
A1: Listado maestro de embalajes de componentes | F1: Modelo: | G1: Constellation 17280.24JC5B | J1: Rev | K1: =+BOM!D2 -> 45953
A2: item | B2: Materialnumber | C2: Material short text | D2: Uso por _Puesto | E2: Puesto línea final | F2: EMBALAJE Proveedor | G2: Embalaje línea | H2: Módulo de abastecimiento | I2: Medio de Abastecimiento | J2: Nivel | K2: Observaciones | L2: __PowerAppsId__ | M2: revisión
A3: 1 | B3: 2T2700025AF | C3: KITS MEXICO/AFRICA | D3: 1 | E3: 0-1 | F3: BCH | G3: Pieza individual | H3: 1 | I3: Carro Bandejas 1 | J3: 1 | L3: 286e1d7f-3e55-4403-8433-ed42b28ab914
A4: 2 | B4: 2T2400019AD | C4: EIXO DIANTEIRO PARA USO AUTOMOTIVO | D4: 1 | E4: A-B | F4: BEX1 | G4: Pieza individual | H4: 1 | I4: Cajón de madera | L4: 23e99f0a-73f5-4d17-a5a0-3622411909ed
A5: 3 | B5: 2T2500048D | C5: EIXO TRASEIRO | D5: 1 | E5: A-B | F5: BEX2 | G5: Pieza individual | H5: 1 | I5: Cajón de madera | L5: 39ae60b9-ac77-4d58-8da4-7a2a65f3da9c
A6: 4 | B6: 2T2601011M | C6: RODA E PNEU | D6: 4 | E6: 4 | F6: BRD | G6: Pieza individual | H6: 3 | I6: rack ruedas | L6: 64e4becd-7125-4882-831c-fe27382e5c96
A7: 5 | B7: 2T2601011N | C7: RODA E PNEU | D7: 3 | E7: 4 | F7: BRD | G7: Pieza individual | H7: 4 | I7: rack ruedas | L7: 234d6ddb-5a2f-47dc-aed1-a21f089c9505
A8: 6 | B8: 2R2899505E | C8: CILINDRO HIDRAULIC | D8: 1 | E8: 0-1 | F8: BX1 | G8: Pieza individual | H8: 1 | I8: Carro Bandejas 1 | J8: 1 | L8: c5fcdee1-60e3-4d61-98d7-9b30b42a3e7d | M8: 45533
A9: 7 | B9: 2T2899365A | C9: TUBO | D9: 1 | E9: 0-1 | F9: BX1 | G9: Pieza individual | H9: 1 | I9: Carro Bandejas 1 | J9: 1 | L9: 287baf35-2eb4-480b-8a9a-e22d7fe622f8
A10: 8 | B10: 2V2899365 | C10: TUBO | D10: 1 | E10: 0-1 | F10: BX1 | G10: Pieza individual | H10: 1 | I10: Carro Bandejas 1 | J10: 1 | L10: e522d5a1-0bab-41b5-ac69-a6a0ef780311
A11: 9 | B11: 22B201512B | C11: FILTRO COMBUSTIVEL PARA USO AUTOMOTIVO | D11: 1 | E11: 0-1 | F11: BX1 | G11: Pieza individual | H11: 1 | I11: Carro Bandejas 1 | J11: 1 | L11: 7da6ba97-5bdd-44df-9a97-0090df2fd9ad
A12: 10 | B12: 2T2711881B | C12: SUPORTE | D12: 1 | E12: 5 | F12: BX1 | G12: Pieza individual | H12: 1 | I12: Carro Bandejas 5 | J12: 1 | L12: 08a26621-9305-4234-b49f-155cbfcf9ced
A13: 11 | B13: 2S2422921B | C13: SUPORTE DE TUBO DIR HIDRAULICA USO AUTOM | D13: 1 | E13: 0-1 | F13: BX1 | G13: Pieza individual | H13: 1 | I13: Carro Bandejas 1 | J13: 2 | L13: a2827873-5a66-400d-a173-47d3dd9be192
A14: 12 | B14: 2T2607891AM | C14: SUPORTE | D14: 1 | E14: 0-1 | F14: BX1 | G14: Pieza individual | H14: 1 | I14: Carro Bandejas 1 | J14: 2 | L14: a4b35ed0-6345-49f5-86f5-a8a71bda6d67
A15: 13 | B15: 2T2711881C | C15: SUPORTE | D15: 1 | E15: 0-1 | F15: BX1 | G15: Pieza individual | H15: 1 | I15: Carro Bandejas 1 | J15: 2 | L15: 80b39d97-0f09-48ce-a813-bebe1cffab4b
A16: 14 | B16: 2T2711881D | C16: SUPORTE | D16: 1 | E16: 0-1 | F16: BX1 | G16: Pieza individual | H16: 1 | I16: Carro Bandejas 1 | J16: 2 | L16: 130e6470-5037-40a0-99e7-99e25777807b
A17: 15 | B17: 2T2863584 | C17: SUPORTE ANTI RUIDO | D17: 1 | E17: 0-1 | F17: BX1 | G17: Pieza individual | H17: 1 | I17: Carro Bandejas 1 | J17: 2 | L17: b7aab5b9-6e6f-482a-9d87-7115fcd25a7f
A18: 16 | B18: 2Z0611767 | C18: DISTANCIADOR | D18: 1 | E18: 0-1 | F18: BX1 | G18: Pieza individual | H18: 1 | I18: Carro Bandejas 1 | J18: 2 | L18: 29553bd6-8014-43c3-b032-292154fa439b
A19: 17 | B19: 2S2253319G | C19: SUPORTE SILENCIOSO | D19: 1 | E19: 0-1 | F19: BX1 | G19: Pieza individual | H19: 1 | I19: Carro Bandejas 1 | J19: 2 | L19: bc6d9311-8d35-491a-a593-94eb11b84ada
A20: 18 | B20: 2T2201513M | C20: SUPORTE | D20: 1 | E20: 0-1 | F20: BX1 | G20: Pieza individual | H20: 1 | I20: Carro Bandejas 1 | J20: 2 | L20: f85fd707-2af6-4b05-b1df-9ef4a721f9c9
A21: 19 | B21: 2S2253319E | C21: SUPORTE LATERAL | D21: 1 | E21: 3 | F21: BX1 | G21: Pieza individual | H21: 1 | I21: Carro Bandejas 3 | J21: 2 | L21: bf83fed7-758c-4441-977c-283fec3fba79 | M21: 45533
A22: 20 | B22: TJG511341 | C22: PINO | D22: 2 | E22: 3 | F22: BX1 | G22: Pieza individual | H22: 2 | I22: Carro Bandejas 3 | J22: 2 | L22: f4aaa217-dab5-4ed1-b332-55c803ce8f16
